<mujoco model="base">
  <compiler angle="radian" meshdir="meshes/" inertiagrouprange="0 0" autolimits="true" />
  <option impratio="20" cone="elliptic" density="1.2" viscosity="0.00002" timestep="0.002" />
  <size nconmax="5000" njmax="5000" />

  <asset>
  <texture builtin="gradient" height="256" rgb1=".9 .9 1." rgb2=".2 .3 .4" type="skybox" width="256" />
    <texture file="C:\Users\Admin\anaconda3\envs\robosuite\lib\site-packages\robosuite\models\assets\arenas\../textures/light-gray-floor-tile.png" type="2d" name="texplane" />
    <material name="floorplane" reflectance="0.01" shininess="0.0" specular="0.0" texrepeat="2 2" texture="texplane" texuniform="true" />
    <texture file="C:\Users\Admin\anaconda3\envs\robosuite\lib\site-packages\robosuite\models\assets\arenas\../textures/steel-scratched.png" type="cube" name="steel-metal" />
    <texture file="C:\Users\Admin\anaconda3\envs\robosuite\lib\site-packages\robosuite\models\assets\arenas\../textures/brass-ambra.png" type="cube" name="brass-metal" />
    <material name="smetal" reflectance="1.0" shininess="1.0" specular="1.0" texrepeat="1 1" texture="steel-metal" texuniform="true" />
    <material name="bmetal" reflectance="1.0" shininess="1.0" specular="1.0" texrepeat="1 1" texture="brass-metal" texuniform="true" />
    
    <texture file="C:\Users\Admin\anaconda3\envs\robosuite\lib\site-packages\robosuite\models\assets\arenas\../textures/ceramic.png" type="cube" name="tex-ceramic" />
    <material name="table_ceramic" reflectance="0.0" shininess="0.0" specular="0.2" texrepeat="1 1" texture="tex-ceramic" />
    
    <texture file="C:\Users\Admin\anaconda3\envs\robosuite\lib\site-packages\robosuite\models\assets\arenas\../textures/steel-brushed.png" type="cube" name="tex-steel-brushed" />
    <material name="table_legs_metal" reflectance="0.8" shininess="0.8" texrepeat="1 1" texture="tex-steel-brushed" />
    
    <texture file="C:\Users\Admin\anaconda3\envs\robosuite\lib\site-packages\robosuite\models\assets\arenas\../textures/light-gray-plaster.png" type="2d" name="tex-light-gray-plaster" />
    <material name="walls_mat" reflectance="0.0" shininess="0.1" specular="0.1" texrepeat="3 3" texture="tex-light-gray-plaster" texuniform="true" />
    
    <texture name="textable" builtin="flat" height="512" width="512" rgb1="0.5 0.5 0.5" rgb2="0.5 0.5 0.5" />
    <material name="table_mat" texture="textable" />

  <mesh name="robot0_base_link" file="C:\Users\Admin\anaconda3\envs\robosuite\lib\site-packages\robosuite\models\assets\robots\kinova3\meshes/base_link.stl" />
    <mesh name="robot0_shoulder_link" file="C:\Users\Admin\anaconda3\envs\robosuite\lib\site-packages\robosuite\models\assets\robots\kinova3\meshes/shoulder_link.stl" />
    <mesh name="robot0_half_arm_1_link" file="C:\Users\Admin\anaconda3\envs\robosuite\lib\site-packages\robosuite\models\assets\robots\kinova3\meshes/half_arm_1_link.stl" />
    <mesh name="robot0_half_arm_2_link" file="C:\Users\Admin\anaconda3\envs\robosuite\lib\site-packages\robosuite\models\assets\robots\kinova3\meshes/half_arm_2_link.stl" />
    <mesh name="robot0_forearm_link" file="C:\Users\Admin\anaconda3\envs\robosuite\lib\site-packages\robosuite\models\assets\robots\kinova3\meshes/forearm_link.stl" />
    <mesh name="robot0_spherical_wrist_1_link" file="C:\Users\Admin\anaconda3\envs\robosuite\lib\site-packages\robosuite\models\assets\robots\kinova3\meshes/spherical_wrist_1_link.stl" />
    <mesh name="robot0_spherical_wrist_2_link" file="C:\Users\Admin\anaconda3\envs\robosuite\lib\site-packages\robosuite\models\assets\robots\kinova3\meshes/spherical_wrist_2_link.stl" />
    <mesh name="robot0_bracelet_with_vision_link" file="C:\Users\Admin\anaconda3\envs\robosuite\lib\site-packages\robosuite\models\assets\robots\kinova3\meshes/bracelet_with_vision_link.stl" />
  <mesh name="fixed_mount0_pedestal" file="C:\Users\Admin\anaconda3\envs\robosuite\lib\site-packages\robosuite\models\assets\bases\meshes/rethink_mount/pedestal.stl" />
    <mesh name="gripper0_right_robotiq_arg2f_base_link" file="C:\Users\Admin\anaconda3\envs\robosuite\lib\site-packages\robosuite\models\assets\grippers\meshes/robotiq_85_gripper/robotiq_arg2f_base_link.stl" />
        <mesh name="gripper0_right_robotiq_arg2f_85_outer_knuckle" file="C:\Users\Admin\anaconda3\envs\robosuite\lib\site-packages\robosuite\models\assets\grippers\meshes/robotiq_85_gripper/robotiq_arg2f_85_outer_knuckle.stl" scale="0.001 0.001 0.001" />
        <mesh name="gripper0_right_robotiq_arg2f_85_outer_finger" file="C:\Users\Admin\anaconda3\envs\robosuite\lib\site-packages\robosuite\models\assets\grippers\meshes/robotiq_85_gripper/robotiq_arg2f_85_outer_finger.stl" scale="0.001 0.001 0.001" />
        <mesh name="gripper0_right_robotiq_arg2f_85_inner_finger" file="C:\Users\Admin\anaconda3\envs\robosuite\lib\site-packages\robosuite\models\assets\grippers\meshes/robotiq_85_gripper/robotiq_arg2f_85_inner_finger.stl" scale="0.001 0.001 0.001" />
        <mesh name="gripper0_right_robotiq_arg2f_85_inner_knuckle" file="C:\Users\Admin\anaconda3\envs\robosuite\lib\site-packages\robosuite\models\assets\grippers\meshes/robotiq_85_gripper/robotiq_arg2f_85_inner_knuckle.stl" scale="0.001 0.001 0.001" />
        <mesh name="gripper0_right_robotiq_arg2f_85_outer_knuckle_vis" file="C:\Users\Admin\anaconda3\envs\robosuite\lib\site-packages\robosuite\models\assets\grippers\meshes/robotiq_85_gripper/robotiq_arg2f_85_outer_knuckle_vis.stl" scale="0.001 0.001 0.001" />
        <mesh name="gripper0_right_robotiq_arg2f_85_outer_finger_vis" file="C:\Users\Admin\anaconda3\envs\robosuite\lib\site-packages\robosuite\models\assets\grippers\meshes/robotiq_85_gripper/robotiq_arg2f_85_outer_finger_vis.stl" scale="0.001 0.001 0.001" />
        <mesh name="gripper0_right_robotiq_arg2f_85_inner_finger_vis" file="C:\Users\Admin\anaconda3\envs\robosuite\lib\site-packages\robosuite\models\assets\grippers\meshes/robotiq_85_gripper/robotiq_arg2f_85_inner_finger_vis.stl" scale="0.001 0.001 0.001" />
        <mesh name="gripper0_right_robotiq_arg2f_85_inner_knuckle_vis" file="C:\Users\Admin\anaconda3\envs\robosuite\lib\site-packages\robosuite\models\assets\grippers\meshes/robotiq_85_gripper/robotiq_arg2f_85_inner_knuckle_vis.stl" scale="0.001 0.001 0.001" />
    <texture file="C:\Users\Admin\anaconda3\envs\robosuite\lib\site-packages\robosuite\models\assets\objects\../textures/brass-ambra.png" type="cube" name="SquareNut_brass-metal" />
    <material name="SquareNut_bmetal" reflectance="1.0" shininess="1.0" specular="1.0" texrepeat="1 1" texture="SquareNut_brass-metal" texuniform="true" />
  <texture file="C:\Users\Admin\anaconda3\envs\robosuite\lib\site-packages\robosuite\models\assets\objects\../textures/steel-scratched.png" type="cube" name="RoundNut1_steel-metal" />
    <material name="RoundNut1_smetal" reflectance="1.0" shininess="1.0" specular="1.0" texrepeat="1 1" texture="RoundNut1_steel-metal" texuniform="true" />
  <texture file="C:\Users\Admin\anaconda3\envs\robosuite\lib\site-packages\robosuite\models\assets\objects\../textures/steel-scratched.png" type="cube" name="RoundNut2_steel-metal" />
    <material name="RoundNut2_smetal" reflectance="1.0" shininess="1.0" specular="1.0" texrepeat="1 1" texture="RoundNut2_steel-metal" texuniform="true" />
  </asset>

  <visual>
    <map znear="0.001" />
  </visual>

  <actuator>
  <motor ctrllimited="true" ctrlrange="-32.0 32.0" joint="robot0_Actuator1" name="robot0_torq_j1" />
    <motor ctrllimited="true" ctrlrange="-32.0 32.0" joint="robot0_Actuator2" name="robot0_torq_j2" />
    <motor ctrllimited="true" ctrlrange="-32.0 32.0" joint="robot0_Actuator3" name="robot0_torq_j3" />
    <motor ctrllimited="true" ctrlrange="-32.0 32.0" joint="robot0_Actuator4" name="robot0_torq_j4" />
    <motor ctrllimited="true" ctrlrange="-32.0 32.0" joint="robot0_Actuator5" name="robot0_torq_j5" />
    <motor ctrllimited="true" ctrlrange="-13.0 13.0" joint="robot0_Actuator6" name="robot0_torq_j6" />
    <motor ctrllimited="true" ctrlrange="-13.0 13.0" joint="robot0_Actuator7" name="robot0_torq_j7" />
  <position name="gripper0_right_finger_1" ctrllimited="true" kp="20" joint="gripper0_right_finger_joint" ctrlrange="0 0.8" />
        <position name="gripper0_right_finger_2" ctrllimited="true" kp="20" joint="gripper0_right_right_outer_knuckle_joint" ctrlrange="0 0.8" />
    </actuator>

  <worldbody>
  <geom condim="3" group="1" material="floorplane" name="floor" pos="0.0 0.0 0.0" size="3 3 .125" type="plane" />
    
    <geom pos="-1.25 2.25 1.5" quat="0.6532815 0.6532815 0.2705981 0.2705981" size="1.06 1.5 0.01" type="box" conaffinity="0" contype="0" group="1" name="wall_leftcorner_visual" material="walls_mat" />
    <geom pos="-1.25 -2.25 1.5" quat="0.6532815 0.6532815 -0.2705981 -0.2705981" size="1.06 1.5 0.01" type="box" conaffinity="0" contype="0" group="1" name="wall_rightcorner_visual" material="walls_mat" />
    <geom pos="1.25 3.0 1.5" quat="0.7071 0.7071 0 0" size="1.75 1.5 0.01" type="box" conaffinity="0" contype="0" group="1" name="wall_left_visual" material="walls_mat" />
    <geom pos="1.25 -3.0 1.5" quat="0.7071 -0.7071 0 0" size="1.75 1.5 0.01" type="box" conaffinity="0" contype="0" group="1" name="wall_right_visual" material="walls_mat" />
    <geom pos="-2.0 0.0 1.5" quat="0.5 0.5 0.5 0.5" size="1.5 1.5 0.01" type="box" conaffinity="0" contype="0" group="1" name="wall_rear_visual" material="walls_mat" />
    <geom pos="3.0 0.0 1.5" quat="0.5 0.5 -0.5 -0.5" size="3 1.5 0.01" type="box" conaffinity="0" contype="0" group="1" name="wall_front_visual" material="walls_mat" />
    
    <body name="table" pos="0.0 0.0 0.7949999999999999">
      <geom pos="0 0 0" size="0.4 0.4 0.025" type="box" group="0" name="table_collision" friction="1 0.005 0.0001" rgba="0.5 0.5 0 1" />
      <geom pos="0 0 0" size="0.4 0.4 0.025" type="box" conaffinity="0" contype="0" group="1" name="table_visual" material="table_ceramic" />
      <site pos="0.0 0.0 0.025" name="table_top" size="0.001 0.001 0.001" rgba="0 0 0 0" />
      
      <geom pos="0.30000000000000004 0.30000000000000004 -0.39749999999999996" size="0.025 0.39749999999999996" type="cylinder" conaffinity="0" contype="0" group="1" name="table_leg1_visual" material="table_legs_metal" />
      <geom pos="-0.30000000000000004 0.30000000000000004 -0.39749999999999996" size="0.025 0.39749999999999996" type="cylinder" conaffinity="0" contype="0" group="1" name="table_leg2_visual" material="table_legs_metal" />
      <geom pos="-0.30000000000000004 -0.30000000000000004 -0.39749999999999996" size="0.025 0.39749999999999996" type="cylinder" conaffinity="0" contype="0" group="1" name="table_leg3_visual" material="table_legs_metal" />
      <geom pos="0.30000000000000004 -0.30000000000000004 -0.39749999999999996" size="0.025 0.39749999999999996" type="cylinder" conaffinity="0" contype="0" group="1" name="table_leg4_visual" material="table_legs_metal" />
    </body>
    <body name="peg1" pos="0.23 0.1 0.85">
      <geom pos="0 0 0" size="0.016 0.016 0.1" type="box" group="0" friction="1 0.005 0.0001" rgba="0.5 0.5 0 1" />
      <geom pos="0 0 0" size="0.016 0.016 0.1" type="box" conaffinity="0" contype="0" group="1" material="bmetal" />
    </body>
    <body name="peg2" pos="0.23 -0.1 0.85">
      <geom pos="0 0 0" size="0.02 0.1" type="cylinder" group="0" friction="1 0.005 0.0001" rgba="0.5 0.5 0 1" />
      <geom pos="0 0 0" size="0.02 0.1" type="cylinder" conaffinity="0" contype="0" group="1" material="smetal" />
    </body>
    <light pos="1.0 1.0 1.5" dir="-0.2 -0.2 -1" specular="0.3 0.3 0.3" directional="true" castshadow="false" />
    
    <camera mode="fixed" name="frontview" pos="1.6 0.0 1.45" quat="0.56 0.43 0.43 0.56" />
    
    <camera mode="fixed" name="birdview" pos="-0.2 0.0 3.0" quat="0.7071 0 0 0.7071" />
    
    <camera mode="fixed" name="agentview" pos="0.5 0.0 1.35" quat="0.653 0.271 0.271 0.653" />
    
    <camera mode="fixed" name="sideview" pos="-0.05651774593317116 1.2761224129427358 1.4879572214102434" quat="0.009905065491771751 0.006877963156909582 0.5912228352893879 0.806418094001364" />
  <body mocap="true" pos="0.0 0.0 -1.0" name="left_eef_target"><geom rgba="0.898 0.420 0.435 0.5" conaffinity="0" contype="0" type="box" size="0.05 0.05 0.05" pos="0 0 0" group="2" name="left_eef_target_box" /><geom rgba="0.898 0.420 0.435 0.8" conaffinity="0" contype="0" type="sphere" size="0.01" pos="0 0 0" group="2" name="left_eef_target_sphere" /></body><body mocap="true" pos="0.0 0.0 -1.0" name="right_eef_target"><geom rgba="0.208 0.314 0.439 0.5" conaffinity="0" contype="0" type="box" size="0.05 0.05 0.05" pos="0 0 0" group="2" name="right_eef_target_box" /><geom rgba="0.208 0.314 0.439 0.8" conaffinity="0" contype="0" type="sphere" size="0.01" pos="0 0 0" group="2" name="right_eef_target_sphere" /></body><body name="robot0_base" pos="0 0 0">
      
      <camera mode="fixed" name="robot0_robotview" pos="1.0 0 0.4" quat="0.653 0.271 0.271 0.653" />
      <inertial diaginertia="0 0 0" mass="0" pos="0 0 0" />
      
      <body name="robot0_fixed_base_link" pos="0 0 0">
        <site name="robot0_right_center" pos="0 0 0" size="0.01" rgba="1 0.3 0.3 1" group="2" />
        <geom type="mesh" contype="0" conaffinity="0" group="1" rgba="1 1 1 1" mesh="robot0_base_link" name="robot0_g0_vis" />
        <geom type="mesh" conaffinity="0" rgba="0 0.5 0 1" mesh="robot0_base_link" name="robot0_base_collision" />
        <body name="robot0_shoulder_link" pos="0 0 0.15643" quat="-3.67321e-06 1 0 0">
          <inertial pos="-2.3e-05 -0.010364 -0.07336" quat="0.707051 0.0451246 -0.0453544 0.704263" mass="1.3773" diaginertia="0.00488868 0.00457 0.00135132" />
          <joint name="robot0_Actuator1" pos="0 0 0" axis="0 0 1" damping="0.1" frictionloss="0.1" armature="5.0" />
          <geom type="mesh" contype="0" conaffinity="0" group="1" rgba="1 1 1 1" name="robot0_s_visual" mesh="robot0_shoulder_link" />
          <geom type="mesh" conaffinity="0" rgba="0 0.5 0 1" mesh="robot0_shoulder_link" name="robot0_s_collision" />
          <body name="robot0_HalfArm1_Link" pos="0 0.005375 -0.12838" quat="0.707105 0.707108 0 0">
            <inertial pos="-4.4e-05 -0.09958 -0.013278" quat="0.482348 0.516286 -0.516862 0.483366" mass="1.1636" diaginertia="0.0113017 0.011088 0.00102532" />
            <joint name="robot0_Actuator2" pos="0 0 0" axis="0 0 1" limited="true" range="-2.41 2.41" damping="0.1" frictionloss="0.1" armature="2.5" />
            <geom type="mesh" contype="0" conaffinity="0" group="1" rgba="1 1 1 1" name="robot0_ha1_visual" mesh="robot0_half_arm_1_link" />
            <geom type="mesh" conaffinity="0" rgba="0 0.5 0 1" mesh="robot0_half_arm_1_link" name="robot0_ha1_collision" />
            <body name="robot0_HalfArm2_Link" pos="0 -0.21038 -0.006375" quat="0.707105 -0.707108 0 0">
              <inertial pos="-4.4e-05 -0.006641 -0.117892" quat="0.706144 0.0213722 -0.0209128 0.707437" mass="1.1636" diaginertia="0.0111633 0.010932 0.00100671" />
              <joint name="robot0_Actuator3" pos="0 0 0" axis="0 0 1" damping="0.1" frictionloss="0.1" armature="1.6666666666666667" />
              <geom type="mesh" contype="0" conaffinity="0" group="1" rgba="1 1 1 1" name="robot0_ha2_visual" mesh="robot0_half_arm_2_link" />
              <geom type="mesh" conaffinity="0" rgba="0 0.5 0 1" mesh="robot0_half_arm_2_link" name="robot0_ha2_collision" />
              <body name="robot0_forearm_link" pos="0 0.006375 -0.21038" quat="0.707105 0.707108 0 0">
                <inertial pos="-1.8e-05 -0.075478 -0.015006" quat="0.483678 0.515961 -0.515859 0.483455" mass="0.9302" diaginertia="0.00834839 0.008147 0.000598606" />
                <joint name="robot0_Actuator4" pos="0 0 0" axis="0 0 1" limited="true" range="-2.66 2.66" damping="0.1" frictionloss="0.1" armature="1.25" />
                <geom type="mesh" contype="0" conaffinity="0" group="1" rgba="1 1 1 1" name="robot0_f_visual" mesh="robot0_forearm_link" />
                <geom type="mesh" conaffinity="0" rgba="0 0.5 0 1" mesh="robot0_forearm_link" name="robot0_f_collision" />
                <body name="robot0_SphericalWrist1_Link" pos="0 -0.20843 -0.006375" quat="0.707105 -0.707108 0 0">
                  <inertial pos="1e-06 -0.009432 -0.063883" quat="0.703558 0.0707492 -0.0707492 0.703558" mass="0.6781" diaginertia="0.00165901 0.001596 0.000346988" />
                  <joint name="robot0_Actuator5" pos="0 0 0" axis="0 0 1" damping="0.1" frictionloss="0.1" armature="1.0" />
                  <geom type="mesh" contype="0" conaffinity="0" group="1" rgba="1 1 1 1" name="robot0_w1_visual" mesh="robot0_spherical_wrist_1_link" />
                  <geom type="mesh" conaffinity="0" rgba="0 0.5 0 1" mesh="robot0_spherical_wrist_1_link" name="robot0_w1_collision" />
                  <body name="robot0_SphericalWrist2_Link" pos="0 0.00017505 -0.10593" quat="0.707105 0.707108 0 0">
                    <inertial pos="1e-06 -0.045483 -0.00965" quat="0.44426 0.550121 -0.550121 0.44426" mass="0.6781" diaginertia="0.00170087 0.001641 0.00035013" />
                    <joint name="robot0_Actuator6" pos="0 0 0" axis="0 0 1" limited="true" range="-2.23 2.23" damping="0.01" frictionloss="0.1" armature="0.8333333333333334" />
                    <geom type="mesh" contype="0" conaffinity="0" group="1" rgba="1 1 1 1" name="robot0_w2_visual" mesh="robot0_spherical_wrist_2_link" />
                    <geom type="mesh" conaffinity="0" rgba="0 0.5 0 1" mesh="robot0_spherical_wrist_2_link" name="robot0_w2_collision" />
                    <body name="robot0_Bracelet_Link" pos="0 -0.10593 -0.00017505" quat="0.707105 -0.707108 0 0">
                      <inertial pos="-0.000281 -0.011402 -0.029798" quat="0.601961 0.40663 -0.381169 0.571843" mass="0.5006" diaginertia="0.000657515 0.000586793 0.000320693" />
                      <joint name="robot0_Actuator7" pos="0 0 0" axis="0 0 1" damping="0.01" frictionloss="0.1" armature="0.7142857142857143" />
                      <geom type="mesh" contype="0" conaffinity="0" group="1" rgba="1 1 1 1" name="robot0_b_visual" mesh="robot0_bracelet_with_vision_link" />
                      <geom type="mesh" conaffinity="0" rgba="0 0.5 0 1" mesh="robot0_bracelet_with_vision_link" name="robot0_b_collision" />
                      <body name="robot0_right_hand" pos="0 0 -0.0615" quat="0 0.707105 -0.707108 0">
                        
                        <camera mode="fixed" name="robot0_eye_in_hand" pos="0.05 0 0" quat="0 0.707108 0.707108 0" fovy="75" />
                        
                      <body name="gripper0_right_robotiq_85_adapter_link" pos="0.0 0 0">
            <site name="gripper0_right_ft_frame" pos="0 0 0" size="0.01 0.01 0.01" rgba="1 0 0 1" type="sphere" group="1" />
            
            <body name="gripper0_right_eef" pos="0 0 0.145" quat="0.707105 0 0 -0.707105">
                <site name="gripper0_right_grip_site" pos="0 0 0" size="0.01 0.01 0.01" rgba="1 0 0 0.5" type="sphere" group="1" />
                <site name="gripper0_right_ee_x" pos="0.1 0 0" size="0.005 .1" quat="0.707105  0 0.707108 0 " rgba="1 0 0 0" type="cylinder" group="1" />
                <site name="gripper0_right_ee_y" pos="0 0.1 0" size="0.005 .1" quat="0.707105 0.707108 0 0" rgba="0 1 0 0" type="cylinder" group="1" />
                <site name="gripper0_right_ee_z" pos="0 0 0.1" size="0.005 .1" quat="1 0 0 0" rgba="0 0 1 0" type="cylinder" group="1" />
                
                <site name="gripper0_right_grip_site_cylinder" pos="0 0 0" size="0.005 10" rgba="0 1 0 0.3" type="cylinder" group="1" />
            </body>
            <inertial pos="0 0 0" mass="0.01" diaginertia="0.001 0.001 0.001" />
            <geom type="mesh" contype="0" conaffinity="0" group="1" rgba="0.1 0.1 0.1 1" name="gripper0_right_hand_visual" mesh="gripper0_right_robotiq_arg2f_base_link" />
            <geom type="mesh" group="0" rgba="0 0 0.5 1" mesh="gripper0_right_robotiq_arg2f_base_link" name="gripper0_right_hand_collision" />
            <body name="gripper0_right_left_outer_knuckle" pos="0 -0.0306011 0.054904" quat="0 0 0 1">
                <inertial pos="0.000163875 0.0554825 -0.0100755" quat="0.920541 0.390623 -0.00362953 0.00231744" mass="0.0311462" diaginertia="5.11372e-05 4.89464e-05 4.95906e-06" />
                <joint name="gripper0_right_finger_joint" pos="0 0 0" axis="1 0 0" limited="true" range="0 0.8" />
                <geom type="mesh" contype="0" conaffinity="0" group="1" rgba="0.792157 0.819608 0.933333 1" name="gripper0_right_left_outer_knuckle_visual" mesh="gripper0_right_robotiq_arg2f_85_outer_knuckle_vis" />
                <geom type="mesh" group="0" rgba="0 0 0.5 1" mesh="gripper0_right_robotiq_arg2f_85_outer_knuckle" name="gripper0_right_left_outer_knuckle_collision" solref="0.01 0.25" />
                <geom pos="0 0.0315 -0.0041" type="mesh" contype="0" conaffinity="0" group="1" rgba="0.1 0.1 0.1 1" name="gripper0_right_left_outer_finger_visual" mesh="gripper0_right_robotiq_arg2f_85_outer_finger_vis" />
                <geom pos="0 0.0315 -0.0041" type="mesh" group="0" rgba="0 0 0.5 1" mesh="gripper0_right_robotiq_arg2f_85_outer_finger" name="gripper0_right_left_outer_finger_collision" solref="0.01 0.25" />
                <body name="gripper0_right_left_inner_finger" pos="0 0.0376 0.043">
                    <inertial pos="0.000199506 0.0032692 0.00175282" quat="0.933621 0.35825 -0.00273441 0.00104851" mass="0.0156391" diaginertia="1.57977e-05 1.51089e-05 1.4647e-06" />
                    <joint name="gripper0_right_left_inner_finger_joint" pos="0 0 0" axis="1 0 0" limited="true" range="-0.8757 0.8757" />
                    <geom type="mesh" contype="0" conaffinity="0" group="1" rgba="0.1 0.1 0.1 1" name="gripper0_right_left_inner_finger_visual" mesh="gripper0_right_robotiq_arg2f_85_inner_finger_vis" />
                    <geom type="mesh" group="0" rgba="0 0 0.5 1" mesh="gripper0_right_robotiq_arg2f_85_inner_finger" name="gripper0_right_left_inner_finger_collision" solref="0.01 0.25" />
                    <geom size="0.011 0.003175 0.01875" pos="0 -0.0220203 0.03242" type="box" contype="0" conaffinity="0" group="1" rgba="0.9 0.9 0.9 1" name="gripper0_right_left_fingertip_visual" />
                    <geom size="0.011 0.003175 0.01875" pos="0 -0.0220203 0.03242" type="box" group="0" rgba="0 0 0.5 1" name="gripper0_right_left_fingertip_collision" solref="0.01 0.25" />
                    <geom size="0.010 0.001 0.01675" pos="0 -0.0245203 0.03242" type="box" group="0" name="gripper0_right_left_fingerpad_collision" rgba="0 0 0.5 1" />
                </body>
            </body>
            <body name="gripper0_right_left_inner_knuckle" pos="0 -0.0127 0.06142" quat="0 0 0 1">
                <inertial pos="0.000123012 0.0507851 0.00103969" quat="0.497203 0.502496 -0.507943 0.492221" mass="0.0271177" diaginertia="2.83809e-05 2.61936e-05 2.81319e-06" />
                <joint name="gripper0_right_left_inner_knuckle_joint" pos="0 0 0" axis="1 0 0" limited="true" range="0 0.8757" />
                <geom type="mesh" contype="0" conaffinity="0" group="1" rgba="0.1 0.1 0.1 1" name="gripper0_right_left_inner_knuckle_visual" mesh="gripper0_right_robotiq_arg2f_85_inner_knuckle_vis" />
                <geom type="mesh" group="0" rgba="0 0 0.5 1" mesh="gripper0_right_robotiq_arg2f_85_inner_knuckle" name="gripper0_right_left_inner_knuckle_collision" />
            </body>
            <body name="gripper0_right_right_outer_knuckle" pos="0 0.0306011 0.054904">
                <inertial pos="0.000163875 0.0554825 -0.0100755" quat="0.920541 0.390623 -0.00362953 0.00231744" mass="0.0311462" diaginertia="5.11372e-05 4.89464e-05 4.95906e-06" />
                <joint name="gripper0_right_right_outer_knuckle_joint" pos="0 0 0" axis="1 0 0" limited="true" range="0 0.8" />
                <geom type="mesh" contype="0" conaffinity="0" group="1" rgba="0.792157 0.819608 0.933333 1" name="gripper0_right_right_outer_knuckle_visual" mesh="gripper0_right_robotiq_arg2f_85_outer_knuckle_vis" />
                <geom type="mesh" group="0" rgba="0 0 0.5 1" mesh="gripper0_right_robotiq_arg2f_85_outer_knuckle" name="gripper0_right_right_outer_knuckle_collision" solref="0.01 0.25" />
                <geom pos="0 0.0315 -0.0041" type="mesh" contype="0" conaffinity="0" group="1" rgba="0.1 0.1 0.1 1" name="gripper0_right_right_outer_finger_visual" mesh="gripper0_right_robotiq_arg2f_85_outer_finger_vis" />
                <geom pos="0 0.0315 -0.0041" type="mesh" group="0" rgba="0 0 0.5 1" mesh="gripper0_right_robotiq_arg2f_85_outer_finger" name="gripper0_right_right_outer_finger_collision" solref="0.01 0.25" />
                <body name="gripper0_right_right_inner_finger" pos="0 0.0376 0.043">
                    <inertial pos="0.000199506 0.0032692 0.00175282" quat="0.933621 0.35825 -0.00273441 0.00104851" mass="0.0156391" diaginertia="1.57977e-05 1.51089e-05 1.4647e-06" />
                    <joint name="gripper0_right_right_inner_finger_joint" pos="0 0 0" axis="1 0 0" limited="true" range="-0.8757 0.8757" />
                    <geom type="mesh" contype="0" conaffinity="0" group="1" rgba="0.1 0.1 0.1 1" name="gripper0_right_right_inner_finger_visual" mesh="gripper0_right_robotiq_arg2f_85_inner_finger_vis" />
                    <geom type="mesh" group="0" rgba="0 0 0.5 1" mesh="gripper0_right_robotiq_arg2f_85_inner_finger" name="gripper0_right_right_inner_finger_collision" solref="0.01 0.25" />
                    <geom size="0.011 0.003175 0.01875" pos="0 -0.0220203 0.03242" type="box" contype="0" conaffinity="0" group="1" rgba="0.9 0.9 0.9 1" name="gripper0_right_right_fingertip_visual" />
                    <geom size="0.011 0.003175 0.01875" pos="0 -0.0220203 0.03242" type="box" group="0" rgba="0 0 0.5 1" name="gripper0_right_right_fingertip_collision" solref="0.01 0.25" />
                    <geom size="0.010 0.001 0.01675" pos="0 -0.0245203 0.03242" type="box" group="0" name="gripper0_right_right_fingerpad_collision" rgba="0 0 0.5 1" />
                </body>
            </body>
            <body name="gripper0_right_right_inner_knuckle" pos="0 0.0127 0.06142">
                <inertial pos="0.000123012 0.0507851 0.00103969" quat="0.497203 0.502496 -0.507943 0.492221" mass="0.0271177" diaginertia="2.83809e-05 2.61936e-05 2.81319e-06" />
                <joint name="gripper0_right_right_inner_knuckle_joint" pos="0 0 0" axis="1 0 0" limited="true" range="0 0.8757" />
                <geom type="mesh" contype="0" conaffinity="0" group="1" rgba="0.1 0.1 0.1 1" name="gripper0_right_right_inner_knuckle_visual" mesh="gripper0_right_robotiq_arg2f_85_inner_knuckle_vis" />
                <geom type="mesh" group="0" rgba="0 0 0.5 1" mesh="gripper0_right_robotiq_arg2f_85_inner_knuckle" name="gripper0_right_right_inner_knuckle_collision" />
            </body>
        </body>
    </body>
                    </body>
                  </body>
                </body>
              </body>
            </body>
          </body>
        </body>
      </body>
    <body name="fixed_mount0_base" pos="0.0 0.0 0.01">
            <body name="fixed_mount0_controller_box" pos="0 0 0">
                <inertial diaginertia="1.71363 1.27988 0.809981" mass="46.64" pos="-0.325 0 -0.38" />
                <geom pos="-0.325 0 -0.38" size="0.11 0.2 0.265" type="box" name="fixed_mount0_controller_box_col" rgba="0.5 0.5 0 1" />
            </body>
            <body name="fixed_mount0_pedestal_feet" pos="0 0 0">
                <inertial diaginertia="8.16095 9.59375 15.0785" mass="167.09" pos="-0.1225 0 -0.758" />
                <geom pos="-0.1225 0 -0.758" size="0.385 0.35 0.155" type="box" name="fixed_mount0_pedestal_feet_col" rgba="0.5 0.5 0 1" />
            </body>
            <body name="fixed_mount0_torso" pos="0 0 0">
                <inertial diaginertia="1e-08 1e-08 1e-08" mass="0.0001" pos="0 0 0" />
                <geom conaffinity="0" contype="0" group="1" pos="0 0 -0.05" size="0.05 0.05 0.05" type="box" name="fixed_mount0_torso_vis" rgba="0.2 0.2 0.2 1" />
            </body>
            <body name="fixed_mount0_pedestal" pos="0 0 0">
                <inertial diaginertia="6.0869 5.81635 4.20915" mass="60.864" pos="0 0 0" quat="0.659267 -0.259505 -0.260945 0.655692" />
                <geom conaffinity="0" contype="0" group="1" mesh="fixed_mount0_pedestal" type="mesh" name="fixed_mount0_pedestal_vis" rgba="0.2 0.2 0.2 1" />
                <geom pos="-0.02 0 -0.29" rgba="0.5 0.5 0 1" size="0.18 0.31" type="cylinder" name="fixed_mount0_pedestal_col" />
            </body>
        </body>
    </body>
  <body name="SquareNut_main">
        <geom pos="-0.03325 0 0" size="0.0105 0.04375 0.01" type="box" solimp="0.998 0.998 0.001" solref="0.02 1" density="100" friction="0.95 0.3 0.2" group="0" condim="4" name="SquareNut_g0" rgba="0.5 0 0 1" />
        <geom pos="0.0 0.03325 0" size="0.03125 0.0105 0.01" type="box" solimp="0.998 0.998 0.001" solref="0.02 1" density="100" friction="0.95 0.3 0.1" group="0" condim="4" name="SquareNut_g1" rgba="0.5 0 0 1" />
        <geom pos="0.0 -0.03325 0" size="0.03125 0.0105 0.01" type="box" solimp="0.998 0.998 0.001" solref="0.02 1" density="100" friction="0.95 0.3 0.1" group="0" condim="4" name="SquareNut_g2" rgba="0.5 0 0 1" />
        <geom pos="0.03325 0 0" size="0.0105 0.04375 0.01" type="box" solimp="0.998 0.998 0.001" solref="0.02 1" density="100" friction="0.95 0.3 0.1" group="0" condim="4" name="SquareNut_g3" rgba="0.5 0 0 1" />
        <geom pos="0.054 0 0" size="0.02525 0.015875 0.01" type="box" solimp="0.998 0.998 0.001" solref="0.02 1" density="100" friction="0.95 0.3 0.1" group="0" condim="4" name="SquareNut_g4" rgba="0.5 0 0 1" />
        <site rgba="1 0 0 1" size="0.005" pos="0.054 0 0" name="SquareNut_handle_site" />
        <site rgba="1 0 0 1" size="0.003" pos="0 0 0" name="SquareNut_center_site" />
      <geom pos="-0.03325 0 0" size="0.0105 0.04375 0.01" type="box" solimp="0.998 0.998 0.001" solref="0.02 1" density="100" friction="0.95 0.3 0.2" group="1" condim="4" material="SquareNut_bmetal" name="SquareNut_g0_visual" conaffinity="0" contype="0" mass="1e-8" />
        <geom pos="0.0 0.03325 0" size="0.03125 0.0105 0.01" type="box" solimp="0.998 0.998 0.001" solref="0.02 1" density="100" friction="0.95 0.3 0.1" group="1" condim="4" material="SquareNut_bmetal" name="SquareNut_g1_visual" conaffinity="0" contype="0" mass="1e-8" />
        <geom pos="0.0 -0.03325 0" size="0.03125 0.0105 0.01" type="box" solimp="0.998 0.998 0.001" solref="0.02 1" density="100" friction="0.95 0.3 0.1" group="1" condim="4" material="SquareNut_bmetal" name="SquareNut_g2_visual" conaffinity="0" contype="0" mass="1e-8" />
        <geom pos="0.03325 0 0" size="0.0105 0.04375 0.01" type="box" solimp="0.998 0.998 0.001" solref="0.02 1" density="100" friction="0.95 0.3 0.1" group="1" condim="4" material="SquareNut_bmetal" name="SquareNut_g3_visual" conaffinity="0" contype="0" mass="1e-8" />
        <geom pos="0.054 0 0" size="0.02525 0.015875 0.01" type="box" solimp="0.998 0.998 0.001" solref="0.02 1" density="100" friction="0.95 0.3 0.1" group="1" condim="4" material="SquareNut_bmetal" name="SquareNut_g4_visual" conaffinity="0" contype="0" mass="1e-8" />
        <joint type="free" damping="0.0005" name="SquareNut_joint0" /><site pos="0 0 0" size="0.002 0.002 0.002" rgba="1 0 0 0" type="sphere" group="0" name="SquareNut_default_site" /></body>
      <body name="RoundNut1_main">
        <geom pos="-0.04245 0 0.0" size="0.01125 0.0225 0.01" type="box" solimp="0.998 0.998 0.001" solref="0.02 1" density="100" friction="0.95 0.3 0.1" group="0" condim="4" name="RoundNut1_g0" rgba="0.5 0 0 1" />
        <geom pos="0.04245 0 0.0" size="0.01125 0.0225 0.01" type="box" solimp="0.998 0.998 0.001" solref="0.02 1" density="100" friction="0.95 0.3 0.1" group="0" condim="4" name="RoundNut1_g1" rgba="0.5 0 0 1" />
        <geom pos="0 -0.04245 0.0" size="0.0225 0.01125 0.01" type="box" solimp="0.998 0.998 0.001" solref="0.02 1" density="100" friction="0.95 0.3 0.1" group="0" condim="4" name="RoundNut1_g2" rgba="0.5 0 0 1" />
        <geom pos="0 0.04245 0.0" size="0.0225 0.01125 0.01" type="box" solimp="0.998 0.998 0.001" solref="0.02 1" density="100" friction="0.95 0.3 0.1" group="0" condim="4" name="RoundNut1_g3" rgba="0.5 0 0 1" />
        <geom pos="-0.03 -0.03 0.0" size="0.01125 0.0225 0.01" axisangle="0 0 1 0.785398" type="box" solimp="0.998 0.998 0.001" solref="0.02 1" density="100" friction="0.95 0.3 0.1" group="0" condim="4" name="RoundNut1_g4" rgba="0.5 0 0 1" />
        <geom pos="0.03 0.03 0.0" size="0.01125 0.0225 0.01" axisangle="0 0 1 0.785398" type="box" solimp="0.998 0.998 0.001" solref="0.02 1" density="100" friction="0.95 0.3 0.1" group="0" condim="4" name="RoundNut1_g5" rgba="0.5 0 0 1" />
        <geom pos="0.03 -0.03 0.0" size="0.0225 0.01125 0.01" axisangle="0 0 1 0.785398" type="box" solimp="0.998 0.998 0.001" solref="0.02 1" density="100" friction="0.95 0.3 0.1" group="0" condim="4" name="RoundNut1_g6" rgba="0.5 0 0 1" />
        <geom pos="-0.03 0.03 0.0" size="0.0225 0.01125 0.01" axisangle="0 0 1 0.785398" type="box" solimp="0.998 0.998 0.001" solref="0.02 1" density="100" friction="0.95 0.3 0.1" group="0" condim="4" name="RoundNut1_g7" rgba="0.5 0 0 1" />
        <geom pos="0.06 0 0.0" size="0.02525 0.015875 0.01" type="box" solimp="0.998 0.998 0.001" solref="0.02 1" density="100" friction="0.95 0.3 0.1" group="0" condim="4" name="RoundNut1_g8" rgba="0.5 0 0 1" />
        <site rgba="1 0 0 1" size="0.005" pos="0.06 0 0.0" name="RoundNut1_handle_site" />
        <site rgba="1 0 0 1" size="0.003" pos="0 0 0" name="RoundNut1_center_site" />
      <geom pos="-0.04245 0 0.0" size="0.01125 0.0225 0.01" type="box" solimp="0.998 0.998 0.001" solref="0.02 1" density="100" friction="0.95 0.3 0.1" group="1" condim="4" material="RoundNut1_smetal" name="RoundNut1_g0_visual" conaffinity="0" contype="0" mass="1e-8" />
        <geom pos="0.04245 0 0.0" size="0.01125 0.0225 0.01" type="box" solimp="0.998 0.998 0.001" solref="0.02 1" density="100" friction="0.95 0.3 0.1" group="1" condim="4" material="RoundNut1_smetal" name="RoundNut1_g1_visual" conaffinity="0" contype="0" mass="1e-8" />
        <geom pos="0 -0.04245 0.0" size="0.0225 0.01125 0.01" type="box" solimp="0.998 0.998 0.001" solref="0.02 1" density="100" friction="0.95 0.3 0.1" group="1" condim="4" material="RoundNut1_smetal" name="RoundNut1_g2_visual" conaffinity="0" contype="0" mass="1e-8" />
        <geom pos="0 0.04245 0.0" size="0.0225 0.01125 0.01" type="box" solimp="0.998 0.998 0.001" solref="0.02 1" density="100" friction="0.95 0.3 0.1" group="1" condim="4" material="RoundNut1_smetal" name="RoundNut1_g3_visual" conaffinity="0" contype="0" mass="1e-8" />
        <geom pos="-0.03 -0.03 0.0" size="0.01125 0.0225 0.01" axisangle="0 0 1 0.785398" type="box" solimp="0.998 0.998 0.001" solref="0.02 1" density="100" friction="0.95 0.3 0.1" group="1" condim="4" material="RoundNut1_smetal" name="RoundNut1_g4_visual" conaffinity="0" contype="0" mass="1e-8" />
        <geom pos="0.03 0.03 0.0" size="0.01125 0.0225 0.01" axisangle="0 0 1 0.785398" type="box" solimp="0.998 0.998 0.001" solref="0.02 1" density="100" friction="0.95 0.3 0.1" group="1" condim="4" material="RoundNut1_smetal" name="RoundNut1_g5_visual" conaffinity="0" contype="0" mass="1e-8" />
        <geom pos="0.03 -0.03 0.0" size="0.0225 0.01125 0.01" axisangle="0 0 1 0.785398" type="box" solimp="0.998 0.998 0.001" solref="0.02 1" density="100" friction="0.95 0.3 0.1" group="1" condim="4" material="RoundNut1_smetal" name="RoundNut1_g6_visual" conaffinity="0" contype="0" mass="1e-8" />
        <geom pos="-0.03 0.03 0.0" size="0.0225 0.01125 0.01" axisangle="0 0 1 0.785398" type="box" solimp="0.998 0.998 0.001" solref="0.02 1" density="100" friction="0.95 0.3 0.1" group="1" condim="4" material="RoundNut1_smetal" name="RoundNut1_g7_visual" conaffinity="0" contype="0" mass="1e-8" />
        <geom pos="0.06 0 0.0" size="0.02525 0.015875 0.01" type="box" solimp="0.998 0.998 0.001" solref="0.02 1" density="100" friction="0.95 0.3 0.1" group="1" condim="4" material="RoundNut1_smetal" name="RoundNut1_g8_visual" conaffinity="0" contype="0" mass="1e-8" />
        <joint type="free" damping="0.0005" name="RoundNut1_joint0" /><site pos="0 0 0" size="0.002 0.002 0.002" rgba="1 0 0 0" type="sphere" group="0" name="RoundNut1_default_site" /></body>
      <body name="RoundNut2_main">
        <geom pos="-0.04245 0 0.0" size="0.01125 0.0225 0.01" type="box" solimp="0.998 0.998 0.001" solref="0.02 1" density="100" friction="0.95 0.3 0.1" group="0" condim="4" name="RoundNut2_g0" rgba="0.5 0 0 1" />
        <geom pos="0.04245 0 0.0" size="0.01125 0.0225 0.01" type="box" solimp="0.998 0.998 0.001" solref="0.02 1" density="100" friction="0.95 0.3 0.1" group="0" condim="4" name="RoundNut2_g1" rgba="0.5 0 0 1" />
        <geom pos="0 -0.04245 0.0" size="0.0225 0.01125 0.01" type="box" solimp="0.998 0.998 0.001" solref="0.02 1" density="100" friction="0.95 0.3 0.1" group="0" condim="4" name="RoundNut2_g2" rgba="0.5 0 0 1" />
        <geom pos="0 0.04245 0.0" size="0.0225 0.01125 0.01" type="box" solimp="0.998 0.998 0.001" solref="0.02 1" density="100" friction="0.95 0.3 0.1" group="0" condim="4" name="RoundNut2_g3" rgba="0.5 0 0 1" />
        <geom pos="-0.03 -0.03 0.0" size="0.01125 0.0225 0.01" axisangle="0 0 1 0.785398" type="box" solimp="0.998 0.998 0.001" solref="0.02 1" density="100" friction="0.95 0.3 0.1" group="0" condim="4" name="RoundNut2_g4" rgba="0.5 0 0 1" />
        <geom pos="0.03 0.03 0.0" size="0.01125 0.0225 0.01" axisangle="0 0 1 0.785398" type="box" solimp="0.998 0.998 0.001" solref="0.02 1" density="100" friction="0.95 0.3 0.1" group="0" condim="4" name="RoundNut2_g5" rgba="0.5 0 0 1" />
        <geom pos="0.03 -0.03 0.0" size="0.0225 0.01125 0.01" axisangle="0 0 1 0.785398" type="box" solimp="0.998 0.998 0.001" solref="0.02 1" density="100" friction="0.95 0.3 0.1" group="0" condim="4" name="RoundNut2_g6" rgba="0.5 0 0 1" />
        <geom pos="-0.03 0.03 0.0" size="0.0225 0.01125 0.01" axisangle="0 0 1 0.785398" type="box" solimp="0.998 0.998 0.001" solref="0.02 1" density="100" friction="0.95 0.3 0.1" group="0" condim="4" name="RoundNut2_g7" rgba="0.5 0 0 1" />
        <geom pos="0.06 0 0.0" size="0.02525 0.015875 0.01" type="box" solimp="0.998 0.998 0.001" solref="0.02 1" density="100" friction="0.95 0.3 0.1" group="0" condim="4" name="RoundNut2_g8" rgba="0.5 0 0 1" />
        <site rgba="1 0 0 1" size="0.005" pos="0.06 0 0.0" name="RoundNut2_handle_site" />
        <site rgba="1 0 0 1" size="0.003" pos="0 0 0" name="RoundNut2_center_site" />
      <geom pos="-0.04245 0 0.0" size="0.01125 0.0225 0.01" type="box" solimp="0.998 0.998 0.001" solref="0.02 1" density="100" friction="0.95 0.3 0.1" group="1" condim="4" material="RoundNut2_smetal" name="RoundNut2_g0_visual" conaffinity="0" contype="0" mass="1e-8" />
        <geom pos="0.04245 0 0.0" size="0.01125 0.0225 0.01" type="box" solimp="0.998 0.998 0.001" solref="0.02 1" density="100" friction="0.95 0.3 0.1" group="1" condim="4" material="RoundNut2_smetal" name="RoundNut2_g1_visual" conaffinity="0" contype="0" mass="1e-8" />
        <geom pos="0 -0.04245 0.0" size="0.0225 0.01125 0.01" type="box" solimp="0.998 0.998 0.001" solref="0.02 1" density="100" friction="0.95 0.3 0.1" group="1" condim="4" material="RoundNut2_smetal" name="RoundNut2_g2_visual" conaffinity="0" contype="0" mass="1e-8" />
        <geom pos="0 0.04245 0.0" size="0.0225 0.01125 0.01" type="box" solimp="0.998 0.998 0.001" solref="0.02 1" density="100" friction="0.95 0.3 0.1" group="1" condim="4" material="RoundNut2_smetal" name="RoundNut2_g3_visual" conaffinity="0" contype="0" mass="1e-8" />
        <geom pos="-0.03 -0.03 0.0" size="0.01125 0.0225 0.01" axisangle="0 0 1 0.785398" type="box" solimp="0.998 0.998 0.001" solref="0.02 1" density="100" friction="0.95 0.3 0.1" group="1" condim="4" material="RoundNut2_smetal" name="RoundNut2_g4_visual" conaffinity="0" contype="0" mass="1e-8" />
        <geom pos="0.03 0.03 0.0" size="0.01125 0.0225 0.01" axisangle="0 0 1 0.785398" type="box" solimp="0.998 0.998 0.001" solref="0.02 1" density="100" friction="0.95 0.3 0.1" group="1" condim="4" material="RoundNut2_smetal" name="RoundNut2_g5_visual" conaffinity="0" contype="0" mass="1e-8" />
        <geom pos="0.03 -0.03 0.0" size="0.0225 0.01125 0.01" axisangle="0 0 1 0.785398" type="box" solimp="0.998 0.998 0.001" solref="0.02 1" density="100" friction="0.95 0.3 0.1" group="1" condim="4" material="RoundNut2_smetal" name="RoundNut2_g6_visual" conaffinity="0" contype="0" mass="1e-8" />
        <geom pos="-0.03 0.03 0.0" size="0.0225 0.01125 0.01" axisangle="0 0 1 0.785398" type="box" solimp="0.998 0.998 0.001" solref="0.02 1" density="100" friction="0.95 0.3 0.1" group="1" condim="4" material="RoundNut2_smetal" name="RoundNut2_g7_visual" conaffinity="0" contype="0" mass="1e-8" />
        <geom pos="0.06 0 0.0" size="0.02525 0.015875 0.01" type="box" solimp="0.998 0.998 0.001" solref="0.02 1" density="100" friction="0.95 0.3 0.1" group="1" condim="4" material="RoundNut2_smetal" name="RoundNut2_g8_visual" conaffinity="0" contype="0" mass="1e-8" />
        <joint type="free" damping="0.0005" name="RoundNut2_joint0" /><site pos="0 0 0" size="0.002 0.002 0.002" rgba="1 0 0 0" type="sphere" group="0" name="RoundNut2_default_site" /></body>
      </worldbody>

  <equality>
  </equality>
<sensor><force name="gripper0_right_force_ee" site="gripper0_right_ft_frame" />
        <torque name="gripper0_right_torque_ee" site="gripper0_right_ft_frame" />
    </sensor><tendon><fixed name="gripper0_right_finger2_12_cpl" range="-1 1" stiffness="0.4" springlength="0.001" limited="true">
			<joint joint="gripper0_right_finger_joint" coef="1" />
			<joint joint="gripper0_right_left_inner_finger_joint" coef="-3" />
			<joint joint="gripper0_right_left_inner_knuckle_joint" coef="1" />
		</fixed>

		
        <fixed name="gripper0_right_finger1_12_cpl" range="-1 1" stiffness="0.4" springlength="0.001" limited="true">
			<joint joint="gripper0_right_right_outer_knuckle_joint" coef="1" />
			<joint joint="gripper0_right_right_inner_finger_joint" coef="-3" />
			<joint joint="gripper0_right_right_inner_knuckle_joint" coef="1" />
		</fixed>
	</tendon><contact /></mujoco>